Workbook
Name Slicer_Account: #N/A
Name Slicer_Date: #N/A
Name Slicer_Security: #N/A

Sheet Internal_Ledger
A1: UniqueKey | B1: Date | C1: Account | D1: Security | E1: Quantity | F1: Value | G1: TradeID
A2: =tbl_Internal[[#This Row],[Account]] & "-" & tbl_Internal[[#This Row],[Security]] & "-" & TEXT(tbl_Internal[[#This Row],[Date]],"yyyymmdd") -> A003-NVDA-20251015 | B2: 45945 | C2: A003 | D2: NVDA | E2: 272 | F2: 78768.44 | G2: T0001
A3: =tbl_Internal[[#This Row],[Account]] & "-" & tbl_Internal[[#This Row],[Security]] & "-" & TEXT(tbl_Internal[[#This Row],[Date]],"yyyymmdd") -> A009-JPM-20251004 | B3: 45934 | C3: A009 | D3: JPM | E3: 392 | F3: 53657.1 | G3: T0002
A4: =tbl_Internal[[#This Row],[Account]] & "-" & tbl_Internal[[#This Row],[Security]] & "-" & TEXT(tbl_Internal[[#This Row],[Date]],"yyyymmdd") -> A008-META-20251008 | B4: 45938 | C4: A008 | D4: META | E4: 90 | F4: 24216.15 | G4: T0003
A5: =tbl_Internal[[#This Row],[Account]] & "-" & tbl_Internal[[#This Row],[Security]] & "-" & TEXT(tbl_Internal[[#This Row],[Date]],"yyyymmdd") -> A005-BABA-20251005 | B5: 45935 | C5: A005 | D5: BABA | E5: 84 | F5: 11371.4 | G5: T0004
A6: =tbl_Internal[[#This Row],[Account]] & "-" & tbl_Internal[[#This Row],[Security]] & "-" & TEXT(tbl_Internal[[#This Row],[Date]],"yyyymmdd") -> A002-META-20251016 | B6: 45946 | C6: A002 | D6: META | E6: 83 | F6: 38215.38 | G6: T0005
A7: =tbl_Internal[[#This Row],[Account]] & "-" & tbl_Internal[[#This Row],[Security]] & "-" & TEXT(tbl_Internal[[#This Row],[Date]],"yyyymmdd") -> A010-BABA-20251018 | B7: 45948 | C7: A010 | D7: BABA | E7: 73 | F7: 12030.2 | G7: T0006
A8: =tbl_Internal[[#This Row],[Account]] & "-" & tbl_Internal[[#This Row],[Security]] & "-" & TEXT(tbl_Internal[[#This Row],[Date]],"yyyymmdd") -> A007-AMZN-20251026 | B8: 45956 | C8: A007 | D8: AMZN | E8: 328 | F8: 88945.42 | G8: T0007
A9: =tbl_Internal[[#This Row],[Account]] & "-" & tbl_Internal[[#This Row],[Security]] & "-" & TEXT(tbl_Internal[[#This Row],[Date]],"yyyymmdd") -> A008-AAPL-20251028 | B9: 45958 | C9: A008 | D9: AAPL | E9: 265 | F9: 128766.49 | G9: T0008
A10: =tbl_Internal[[#This Row],[Account]] & "-" & tbl_Internal[[#This Row],[Security]] & "-" & TEXT(tbl_Internal[[#This Row],[Date]],"yyyymmdd") -> A005-MSFT-20251028 | B10: 45958 | C10: A005 | D10: MSFT | E10: 245 | F10: 68380.25 | G10: T0009
A11: =tbl_Internal[[#This Row],[Account]] & "-" & tbl_Internal[[#This Row],[Security]] & "-" & TEXT(tbl_Internal[[#This Row],[Date]],"yyyymmdd") -> A003-TSLA-20251029 | B11: 45959 | C11: A003 | D11: TSLA | E11: 329 | F11: 132259.07 | G11: T0010
A12: =tbl_Internal[[#This Row],[Account]] & "-" & tbl_Internal[[#This Row],[Security]] & "-" & TEXT(tbl_Internal[[#This Row],[Date]],"yyyymmdd") -> A003-NVDA-20251018 | B12: 45948 | C12: A003 | D12: NVDA | E12: 249 | F12: 54431.19 | G12: T0011
A13: =tbl_Internal[[#This Row],[Account]] & "-" & tbl_Internal[[#This Row],[Security]] & "-" & TEXT(tbl_Internal[[#This Row],[Date]],"yyyymmdd") -> A010-GOOGL-20251016 | B13: 45946 | C13: A010 | D13: GOOGL | E13: 383 | F13: 91763.28 | G13: T0012
... A101: =tbl_Internal[[#This Row],[Account]] & "-" & tbl_Internal[[#This Row],[Security]] & "-" & TEXT(tbl_Internal[[#This Row],[Date]],"yyyymmdd") -> A009-AAPL-20251028 | B101: 45958 | C101: A009 | D101: AAPL | E101: 323 | F101: 110989.27 | G101: T0100

Sheet Custodian_Statement
A1: UniqueKey | B1: Date | C1: Account | D1: Security | E1: Quantity | F1: Value | G1: TradeID
A2: =tbl_Custodian[[#This Row],[Account]] & "-" & tbl_Custodian[[#This Row],[Security]] & "-" & TEXT(tbl_Custodian[[#This Row],[Date]],"yyyymmdd") -> A004-JPM-20251024 | B2: 45954 | C2: A004 | D2: JPM | E2: 445 | F2: 53599.16 | G2: T0092
A3: =tbl_Custodian[[#This Row],[Account]] & "-" & tbl_Custodian[[#This Row],[Security]] & "-" & TEXT(tbl_Custodian[[#This Row],[Date]],"yyyymmdd") -> A002-BABA-20251013 | B3: 45943 | C3: A002 | D3: BABA | E3: 89 | F3: 26500.623 | G3: T0044
A4: =tbl_Custodian[[#This Row],[Account]] & "-" & tbl_Custodian[[#This Row],[Security]] & "-" & TEXT(tbl_Custodian[[#This Row],[Date]],"yyyymmdd") -> A003-MSFT-20251014 | B4: 45944 | C4: A003 | D4: MSFT | E4: 324 | F4: 104846.25 | G4: T0051
A5: =tbl_Custodian[[#This Row],[Account]] & "-" & tbl_Custodian[[#This Row],[Security]] & "-" & TEXT(tbl_Custodian[[#This Row],[Date]],"yyyymmdd") -> A001-AAPL-20251005 | B5: 45935 | C5: A001 | D5: AAPL | E5: 368 | F5: 122032.52 | G5: T0091
A6: =tbl_Custodian[[#This Row],[Account]] & "-" & tbl_Custodian[[#This Row],[Security]] & "-" & TEXT(tbl_Custodian[[#This Row],[Date]],"yyyymmdd") -> A003-NVDA-20251023 | B6: 45953 | C6: A003 | D6: NVDA | E6: 288 | F6: 105904.83 | G6: T0018
A7: =tbl_Custodian[[#This Row],[Account]] & "-" & tbl_Custodian[[#This Row],[Security]] & "-" & TEXT(tbl_Custodian[[#This Row],[Date]],"yyyymmdd") -> A008-AAPL-20251028 | B7: 45958 | C7: A008 | D7: AAPL | E7: 265 | F7: 128766.49 | G7: T0008
A8: =tbl_Custodian[[#This Row],[Account]] & "-" & tbl_Custodian[[#This Row],[Security]] & "-" & TEXT(tbl_Custodian[[#This Row],[Date]],"yyyymmdd") -> A009-TSLA-20251027 | B8: 45957 | C8: A009 | D8: TSLA | E8: 281 | F8: 100183.03 | G8: T0023
A9: =tbl_Custodian[[#This Row],[Account]] & "-" & tbl_Custodian[[#This Row],[Security]] & "-" & TEXT(tbl_Custodian[[#This Row],[Date]],"yyyymmdd") -> A004-AAPL-20251009 | B9: 45939 | C9: A004 | D9: AAPL | E9: 195 | F9: 24693.22 | G9: T0086
A10: =tbl_Custodian[[#This Row],[Account]] & "-" & tbl_Custodian[[#This Row],[Security]] & "-" & TEXT(tbl_Custodian[[#This Row],[Date]],"yyyymmdd") -> A005-NVDA-20251021 | B10: 45951 | C10: A005 | D10: NVDA | E10: 59 | F10: 10361.47 | G10: T0081
A11: =tbl_Custodian[[#This Row],[Account]] & "-" & tbl_Custodian[[#This Row],[Security]] & "-" & TEXT(tbl_Custodian[[#This Row],[Date]],"yyyymmdd") -> A010-NVDA-20251002 | B11: 45932 | C11: A010 | D11: NVDA | E11: 223 | F11: 75896.03 | G11: T0046
A12: =tbl_Custodian[[#This Row],[Account]] & "-" & tbl_Custodian[[#This Row],[Security]] & "-" & TEXT(tbl_Custodian[[#This Row],[Date]],"yyyymmdd") -> A005-NVDA-20251014 | B12: 45944 | C12: A005 | D12: NVDA | E12: 153 | F12: 61211.14 | G12: T0039
A13: =tbl_Custodian[[#This Row],[Account]] & "-" & tbl_Custodian[[#This Row],[Security]] & "-" & TEXT(tbl_Custodian[[#This Row],[Date]],"yyyymmdd") -> A006-META-20251018 | B13: 45948 | C13: A006 | D13: META | E13: 232 | F13: 55287.62 | G13: T0096
... A101: =tbl_Custodian[[#This Row],[Account]] & "-" & tbl_Custodian[[#This Row],[Security]] & "-" & TEXT(tbl_Custodian[[#This Row],[Date]],"yyyymmdd") -> A007-AMZN-20251026 | B101: 45956 | C101: A007 | D101: AMZN | E101: 328 | F101: 88945.42 | G101: T0007

Sheet Reconciliation
A1: UniqueKey | B1: Date | C1: Account | D1: Security | E1: Internal_Quantity | F1: Internal_Value | G1: Custodian_Quantity | H1: Custodian_Value | I1: Quantity_Diff | J1: Value_Diff | K1: Match_Status
A2: =tbl_Internal[[#This Row],[Account]] & "-" & tbl_Internal[[#This Row],[Security]] & "-" & TEXT(tbl_Internal[[#This Row],[Date]],"yyyymmdd") -> A003-NVDA-20251015 | B2: =VLOOKUP(A2, tbl_Internal[], 2, FALSE) -> 45945 | C2: =VLOOKUP(A2, tbl_Internal[], 3, FALSE) -> A003 | D2: =VLOOKUP(A2, tbl_Internal[], 4, FALSE) -> NVDA | E2: =IFERROR(VLOOKUP(A2, tbl_Internal[], 5, FALSE), "") -> 272 | F2: =IFERROR(VLOOKUP(A2, tbl_Internal[], 6, FALSE), "") -> 78768.44 | G2: =IFERROR(VLOOKUP(A2, tbl_Custodian[], 5, FALSE), "") -> 272 | H2: =IFERROR(VLOOKUP(A2, tbl_Custodian[], 6, FALSE), "") -> 78768.44 | I2: =IF(E2="", "", E2 - G2) -> 0 | J2: =IF(F2="", "", F2 - H2) -> 0 | K2: =IF(AND(I2=0, J2=0), "MATCH", "MISMATCH") -> MATCH
A3: =tbl_Internal[[#This Row],[Account]] & "-" & tbl_Internal[[#This Row],[Security]] & "-" & TEXT(tbl_Internal[[#This Row],[Date]],"yyyymmdd") -> A009-JPM-20251004 | B3: =VLOOKUP(A3, tbl_Internal[], 2, FALSE) -> 45934 | C3: =VLOOKUP(A3, tbl_Internal[], 3, FALSE) -> A009 | D3: =VLOOKUP(A3, tbl_Internal[], 4, FALSE) -> JPM | E3: =IFERROR(VLOOKUP(A3, tbl_Internal[], 5, FALSE), "") -> 392 | F3: =IFERROR(VLOOKUP(A3, tbl_Internal[], 6, FALSE), "") -> 53657.1 | G3: =IFERROR(VLOOKUP(A3, tbl_Custodian[], 5, FALSE), "") -> 392 | H3: =IFERROR(VLOOKUP(A3, tbl_Custodian[], 6, FALSE), "") -> 53657.1 | I3: =IF(E3="", "", E3 - G3) -> 0 | J3: =IF(F3="", "", F3 - H3) -> 0 | K3: =IF(AND(I3=0, J3=0), "MATCH", "MISMATCH") -> MATCH
A4: =tbl_Internal[[#This Row],[Account]] & "-" & tbl_Internal[[#This Row],[Security]] & "-" & TEXT(tbl_Internal[[#This Row],[Date]],"yyyymmdd") -> A008-META-20251008 | B4: =VLOOKUP(A4, tbl_Internal[], 2, FALSE) -> 45938 | C4: =VLOOKUP(A4, tbl_Internal[], 3, FALSE) -> A008 | D4: =VLOOKUP(A4, tbl_Internal[], 4, FALSE) -> META | E4: =IFERROR(VLOOKUP(A4, tbl_Internal[], 5, FALSE), "") -> 90 | F4: =IFERROR(VLOOKUP(A4, tbl_Internal[], 6, FALSE), "") -> 24216.15 | G4: =IFERROR(VLOOKUP(A4, tbl_Custodian[], 5, FALSE), "") -> 90 | H4: =IFERROR(VLOOKUP(A4, tbl_Custodian[], 6, FALSE), "") -> 24216.15 | I4: =IF(E4="", "", E4 - G4) -> 0 | J4: =IF(F4="", "", F4 - H4) -> 0 | K4: =IF(AND(I4=0, J4=0), "MATCH", "MISMATCH") -> MATCH
A5: =tbl_Internal[[#This Row],[Account]] & "-" & tbl_Internal[[#This Row],[Security]] & "-" & TEXT(tbl_Internal[[#This Row],[Date]],"yyyymmdd") -> A005-BABA-20251005 | B5: =VLOOKUP(A5, tbl_Internal[], 2, FALSE) -> 45935 | C5: =VLOOKUP(A5, tbl_Internal[], 3, FALSE) -> A005 | D5: =VLOOKUP(A5, tbl_Internal[], 4, FALSE) -> BABA | E5: =IFERROR(VLOOKUP(A5, tbl_Internal[], 5, FALSE), "") -> 84 | F5: =IFERROR(VLOOKUP(A5, tbl_Internal[], 6, FALSE), "") -> 11371.4 | G5: =IFERROR(VLOOKUP(A5, tbl_Custodian[], 5, FALSE), "") -> 84 | H5: =IFERROR(VLOOKUP(A5, tbl_Custodian[], 6, FALSE), "") -> 11371.4 | I5: =IF(E5="", "", E5 - G5) -> 0 | J5: =IF(F5="", "", F5 - H5) -> 0 | K5: =IF(AND(I5=0, J5=0), "MATCH", "MISMATCH") -> MATCH
A6: =tbl_Internal[[#This Row],[Account]] & "-" & tbl_Internal[[#This Row],[Security]] & "-" & TEXT(tbl_Internal[[#This Row],[Date]],"yyyymmdd") -> A002-META-20251016 | B6: =VLOOKUP(A6, tbl_Internal[], 2, FALSE) -> 45946 | C6: =VLOOKUP(A6, tbl_Internal[], 3, FALSE) -> A002 | D6: =VLOOKUP(A6, tbl_Internal[], 4, FALSE) -> META | E6: =IFERROR(VLOOKUP(A6, tbl_Internal[], 5, FALSE), "") -> 83 | F6: =IFERROR(VLOOKUP(A6, tbl_Internal[], 6, FALSE), "") -> 38215.38 | G6: =IFERROR(VLOOKUP(A6, tbl_Custodian[], 5, FALSE), "") -> 83 | H6: =IFERROR(VLOOKUP(A6, tbl_Custodian[], 6, FALSE), "") -> 38215.38 | I6: =IF(E6="", "", E6 - G6) -> 0 | J6: =IF(F6="", "", F6 - H6) -> 0 | K6: =IF(AND(I6=0, J6=0), "MATCH", "MISMATCH") -> MATCH
A7: =tbl_Internal[[#This Row],[Account]] & "-" & tbl_Internal[[#This Row],[Security]] & "-" & TEXT(tbl_Internal[[#This Row],[Date]],"yyyymmdd") -> A010-BABA-20251018 | B7: =VLOOKUP(A7, tbl_Internal[], 2, FALSE) -> 45948 | C7: =VLOOKUP(A7, tbl_Internal[], 3, FALSE) -> A010 | D7: =VLOOKUP(A7, tbl_Internal[], 4, FALSE) -> BABA | E7: =IFERROR(VLOOKUP(A7, tbl_Internal[], 5, FALSE), "") -> 73 | F7: =IFERROR(VLOOKUP(A7, tbl_Internal[], 6, FALSE), "") -> 12030.2 | G7: =IFERROR(VLOOKUP(A7, tbl_Custodian[], 5, FALSE), "") -> 73 | H7: =IFERROR(VLOOKUP(A7, tbl_Custodian[], 6, FALSE), "") -> 12030.2 | I7: =IF(E7="", "", E7 - G7) -> 0 | J7: =IF(F7="", "", F7 - H7) -> 0 | K7: =IF(AND(I7=0, J7=0), "MATCH", "MISMATCH") -> MATCH
A8: =tbl_Internal[[#This Row],[Account]] & "-" & tbl_Internal[[#This Row],[Security]] & "-" & TEXT(tbl_Internal[[#This Row],[Date]],"yyyymmdd") -> A007-AMZN-20251026 | B8: =VLOOKUP(A8, tbl_Internal[], 2, FALSE) -> 45956 | C8: =VLOOKUP(A8, tbl_Internal[], 3, FALSE) -> A007 | D8: =VLOOKUP(A8, tbl_Internal[], 4, FALSE) -> AMZN | E8: =IFERROR(VLOOKUP(A8, tbl_Internal[], 5, FALSE), "") -> 328 | F8: =IFERROR(VLOOKUP(A8, tbl_Internal[], 6, FALSE), "") -> 88945.42 | G8: =IFERROR(VLOOKUP(A8, tbl_Custodian[], 5, FALSE), "") -> 328 | H8: =IFERROR(VLOOKUP(A8, tbl_Custodian[], 6, FALSE), "") -> 88945.42 | I8: =IF(E8="", "", E8 - G8) -> 0 | J8: =IF(F8="", "", F8 - H8) -> 0 | K8: =IF(AND(I8=0, J8=0), "MATCH", "MISMATCH") -> MATCH
A9: =tbl_Internal[[#This Row],[Account]] & "-" & tbl_Internal[[#This Row],[Security]] & "-" & TEXT(tbl_Internal[[#This Row],[Date]],"yyyymmdd") -> A008-AAPL-20251028 | B9: =VLOOKUP(A9, tbl_Internal[], 2, FALSE) -> 45958 | C9: =VLOOKUP(A9, tbl_Internal[], 3, FALSE) -> A008 | D9: =VLOOKUP(A9, tbl_Internal[], 4, FALSE) -> AAPL | E9: =IFERROR(VLOOKUP(A9, tbl_Internal[], 5, FALSE), "") -> 265 | F9: =IFERROR(VLOOKUP(A9, tbl_Internal[], 6, FALSE), "") -> 128766.49 | G9: =IFERROR(VLOOKUP(A9, tbl_Custodian[], 5, FALSE), "") -> 265 | H9: =IFERROR(VLOOKUP(A9, tbl_Custodian[], 6, FALSE), "") -> 128766.49 | I9: =IF(E9="", "", E9 - G9) -> 0 | J9: =IF(F9="", "", F9 - H9) -> 0 | K9: =IF(AND(I9=0, J9=0), "MATCH", "MISMATCH") -> MATCH
A10: =tbl_Internal[[#This Row],[Account]] & "-" & tbl_Internal[[#This Row],[Security]] & "-" & TEXT(tbl_Internal[[#This Row],[Date]],"yyyymmdd") -> A005-MSFT-20251028 | B10: =VLOOKUP(A10, tbl_Internal[], 2, FALSE) -> 45958 | C10: =VLOOKUP(A10, tbl_Internal[], 3, FALSE) -> A005 | D10: =VLOOKUP(A10, tbl_Internal[], 4, FALSE) -> MSFT | E10: =IFERROR(VLOOKUP(A10, tbl_Internal[], 5, FALSE), "") -> 245 | F10: =IFERROR(VLOOKUP(A10, tbl_Internal[], 6, FALSE), "") -> 68380.25 | G10: =IFERROR(VLOOKUP(A10, tbl_Custodian[], 5, FALSE), "") -> 245 | H10: =IFERROR(VLOOKUP(A10, tbl_Custodian[], 6, FALSE), "") -> 68380.25 | I10: =IF(E10="", "", E10 - G10) -> 0 | J10: =IF(F10="", "", F10 - H10) -> 0 | K10: =IF(AND(I10=0, J10=0), "MATCH", "MISMATCH") -> MATCH
A11: =tbl_Internal[[#This Row],[Account]] & "-" & tbl_Internal[[#This Row],[Security]] & "-" & TEXT(tbl_Internal[[#This Row],[Date]],"yyyymmdd") -> A003-TSLA-20251029 | B11: =VLOOKUP(A11, tbl_Internal[], 2, FALSE) -> 45959 | C11: =VLOOKUP(A11, tbl_Internal[], 3, FALSE) -> A003 | D11: =VLOOKUP(A11, tbl_Internal[], 4, FALSE) -> TSLA | E11: =IFERROR(VLOOKUP(A11, tbl_Internal[], 5, FALSE), "") -> 329 | F11: =IFERROR(VLOOKUP(A11, tbl_Internal[], 6, FALSE), "") -> 132259.07 | G11: =IFERROR(VLOOKUP(A11, tbl_Custodian[], 5, FALSE), "") -> 329 | H11: =IFERROR(VLOOKUP(A11, tbl_Custodian[], 6, FALSE), "") -> 132259.07 | I11: =IF(E11="", "", E11 - G11) -> 0 | J11: =IF(F11="", "", F11 - H11) -> 0 | K11: =IF(AND(I11=0, J11=0), "MATCH", "MISMATCH") -> MATCH
A12: =tbl_Internal[[#This Row],[Account]] & "-" & tbl_Internal[[#This Row],[Security]] & "-" & TEXT(tbl_Internal[[#This Row],[Date]],"yyyymmdd") -> A003-NVDA-20251018 | B12: =VLOOKUP(A12, tbl_Internal[], 2, FALSE) -> 45948 | C12: =VLOOKUP(A12, tbl_Internal[], 3, FALSE) -> A003 | D12: =VLOOKUP(A12, tbl_Internal[], 4, FALSE) -> NVDA | E12: =IFERROR(VLOOKUP(A12, tbl_Internal[], 5, FALSE), "") -> 249 | F12: =IFERROR(VLOOKUP(A12, tbl_Internal[], 6, FALSE), "") -> 54431.19 | G12: =IFERROR(VLOOKUP(A12, tbl_Custodian[], 5, FALSE), "") -> 249 | H12: =IFERROR(VLOOKUP(A12, tbl_Custodian[], 6, FALSE), "") -> 54045.449 | I12: =IF(E12="", "", E12 - G12) -> 0 | J12: =IF(F12="", "", F12 - H12) -> 385.7406 | K12: =IF(AND(I12=0, J12=0), "MATCH", "MISMATCH") -> MISMATCH
A13: =tbl_Internal[[#This Row],[Account]] & "-" & tbl_Internal[[#This Row],[Security]] & "-" & TEXT(tbl_Internal[[#This Row],[Date]],"yyyymmdd") -> A010-GOOGL-20251016 | B13: =VLOOKUP(A13, tbl_Internal[], 2, FALSE) -> 45946 | C13: =VLOOKUP(A13, tbl_Internal[], 3, FALSE) -> A010 | D13: =VLOOKUP(A13, tbl_Internal[], 4, FALSE) -> GOOGL | E13: =IFERROR(VLOOKUP(A13, tbl_Internal[], 5, FALSE), "") -> 383 | F13: =IFERROR(VLOOKUP(A13, tbl_Internal[], 6, FALSE), "") -> 91763.28 | G13: =IFERROR(VLOOKUP(A13, tbl_Custodian[], 5, FALSE), "") -> 383 | H13: =IFERROR(VLOOKUP(A13, tbl_Custodian[], 6, FALSE), "") -> 91763.28 | I13: =IF(E13="", "", E13 - G13) -> 0 | J13: =IF(F13="", "", F13 - H13) -> 0 | K13: =IF(AND(I13=0, J13=0), "MATCH", "MISMATCH") -> MATCH
... A101: =tbl_Internal[[#This Row],[Account]] & "-" & tbl_Internal[[#This Row],[Security]] & "-" & TEXT(tbl_Internal[[#This Row],[Date]],"yyyymmdd") -> A009-AAPL-20251028 | B101: =VLOOKUP(A101, tbl_Internal[], 2, FALSE) -> 45958 | C101: =VLOOKUP(A101, tbl_Internal[], 3, FALSE) -> A009 | D101: =VLOOKUP(A101, tbl_Internal[], 4, FALSE) -> AAPL | E101: =IFERROR(VLOOKUP(A101, tbl_Internal[], 5, FALSE), "") -> 323 | F101: =IFERROR(VLOOKUP(A101, tbl_Internal[], 6, FALSE), "") -> 110989.27 | G101: =IFERROR(VLOOKUP(A101, tbl_Custodian[], 5, FALSE), "") -> 323 | H101: =IFERROR(VLOOKUP(A101, tbl_Custodian[], 6, FALSE), "") -> 111407.71 | I101: =IF(E101="", "", E101 - G101) -> 0 | J101: =IF(F101="", "", F101 - H101) -> -418.43567 | K101: =IF(AND(I101=0, J101=0), "MATCH", "MISMATCH") -> MISMATCH

Sheet Dashboard
A2: Total Transactions | B2: =COUNTA(Reconciliation!A:A)-1 -> 100
A3: Matched | B3: =COUNTIF(Reconciliation!K:K,"MATCH") -> 90
A4: Mismatched | B4: =COUNTIF(Reconciliation!K:K,"MISMATCH") -> 10
A5: Match % | B5: =B3/B2 -> 0.9
A10: Status | B10: Count
A11: MATCH | B11: =COUNTIF(Reconciliation!K:K,"MATCH") -> 90
A12: MISMATCH | B12: =COUNTIF(Reconciliation!K:K,"MISMATCH") -> 10
A20: UniqueKey | B20: Quantity_Diff | C20: Value_Diff
A21: A003-NVDA-20251018 | B21: 0 | C21: 385.7406
A22: A003-NVDA-20251015 | B22: 0 | C22: 0
A23: A009-JPM-20251004 | B23: 0 | C23: 0
A24: A008-META-20251008 | B24: 0 | C24: 0
A25: A005-BABA-20251005 | B25: 0 | C25: 0
A26: A002-META-20251016 | B26: 0 | C26: 0
A27: A010-BABA-20251018 | B27: 0 | C27: 0
A28: A007-AMZN-20251026 | B28: 0 | C28: 0
A29: A008-AAPL-20251028 | B29: 0 | C29: 0 | H29: Match_Status | I29: MISMATCH
A30: A005-MSFT-20251028 | B30: 0 | C30: 0
A31: A003-TSLA-20251029 | B31: 0 | C31: 0 | H31: Row Labels | I31: Count of Match_Status
A32: A010-GOOGL-20251016 | B32: 0 | C32: 0 | H32: A001-BABA-20251017 | I32: 1
A33: A008-NFLX-20251027 | B33: -4 | C33: 0 | H33: A002-BABA-20251013 | I33: 1
A34: A010-BABA-20251024 | B34: 0 | C34: 0 | H34: A002-META-20251017 | I34: 1
A35: A006-META-20251027 | B35: 0 | C35: 0 | H35: A003-NVDA-20251018 | I35: 1
A36: A009-GOOGL-20251009 | B36: 0 | C36: 0 | H36: A003-NVDA-20251021 | I36: 1
A37: A001-MSFT-20251024 | B37: 0 | C37: 0 | H37: A008-AAPL-20251030 | I37: 1
A38: A003-NVDA-20251023 | B38: 0 | C38: 0 | H38: A008-NFLX-20251027 | I38: 1
A39: A001-BABA-20251005 | B39: 0 | C39: 0 | H39: A009-AAPL-20251028 | I39: 1
A40: A001-JPM-20251001 | B40: 0 | C40: 0 | H40: A009-BABA-20251008 | I40: 1
A41: A004-AMZN-20251001 | B41: 0 | C41: 0 | H41: A010-NVDA-20251017 | I41: 1
A42: A003-META-20251011 | B42: 0 | C42: 0 | H42: Grand Total | I42: 10
A43: A009-TSLA-20251027 | B43: 0 | C43: 0
A44: A010-AAPL-20251029 | B44: 0 | C44: 0
A45: A007-TSLA-20251008 | B45: 0 | C45: 0
A46: A007-JPM-20251005 | B46: 0 | C46: 0
A47: A005-JPM-20251021 | B47: 0 | C47: 0
A48: A005-META-20251020 | B48: 0 | C48: 0
A49: A009-NFLX-20251011 | B49: 0 | C49: 0
A50: A010-MSFT-20251029 | B50: 0 | C50: 0
A51: A002-GOOGL-20251029 | B51: 0 | C51: 0
A52: A006-AMZN-20251008 | B52: 0 | C52: 0
...
